{
 "cells": [
  {
   "cell_type": "code",
   "execution_count": 22,
   "metadata": {},
   "outputs": [],
   "source": [
    "import csv\n",
    "import numpy as np\n",
    "import tensorflow as tf\n",
    "from scipy.stats import norm\n",
    "from scipy.stats import uniform"
   ]
  },
  {
   "cell_type": "markdown",
   "metadata": {},
   "source": [
    "## CNN vs. DNN"
   ]
  },
  {
   "cell_type": "code",
   "execution_count": null,
   "metadata": {},
   "outputs": [],
   "source": []
  },
  {
   "cell_type": "code",
   "execution_count": null,
   "metadata": {},
   "outputs": [],
   "source": []
  },
  {
   "cell_type": "markdown",
   "metadata": {},
   "source": [
    "## Generate Data\n",
    "(Skip this if you want to use already generated data) \n",
    "\n",
    "Make sure that the parameters below where the same when training the networks"
   ]
  },
  {
   "cell_type": "code",
   "execution_count": 23,
   "metadata": {},
   "outputs": [],
   "source": [
    "num_strikes = 12\n",
    "num_maturities = 12\n",
    "num_sample_patches = 1\n",
    "num_data_points = num_strikes * num_maturities * num_sample_patches\n",
    "\n",
    "\n",
    "#initial values\n",
    "S0 = 1.0\n",
    "V0 = 0.2\n",
    "r = 0.15\n",
    "\n",
    "num_model_params = 3\n",
    "num_contract_params = 2\n",
    "\n",
    "contract_bounds = np.array([[0.7*S0,1.3*S0],[1,10]]) #bounds for K,T\n",
    "model_bounds = np.array([[0,5],[0,1],[0,1]]) #bounds for alpha,beta,rho, make sure alpha>0, beta,rho \\in [0,1]\n",
    "\n",
    "# make sure does distances are the same in output grid approach and image input for cnn\n",
    "maturities_distance = (contract_bounds[1,1]-contract_bounds[1,0])/(2*num_maturities) \n",
    "strikes_distance = (contract_bounds[0,1]-contract_bounds[0,0])/(2*num_strikes)\n",
    "\n",
    "alpha_true = 1.0\n",
    "beta_true = 0.5\n",
    "rho_true = 0.2"
   ]
  },
  {
   "cell_type": "code",
   "execution_count": 41,
   "metadata": {},
   "outputs": [],
   "source": [
    "def corr_brownian_motion(n, T, dim, rho):\n",
    "    dt = T/n\n",
    "\n",
    "    dW1 = norm.rvs(size=(dim,n+1) , scale=np.sqrt(dt))\n",
    "    dW2 = rho * dW1 + np.sqrt(1 - np.power(rho ,2)) * norm.rvs(size=(dim,n+1) , scale=np.sqrt(dt))\n",
    "        \n",
    "    W1 = np.cumsum(dW1, axis=-1)\n",
    "    W2 = np.cumsum(dW2, axis=-1)\n",
    " \n",
    "    return W1,W2\n",
    "\n",
    "def euler_maruyama(mu,sigma,T,x0,W):\n",
    "    dim = W.shape[0]\n",
    "    n = W.shape[1]-1\n",
    "    Y = np.zeros((dim,n+1))\n",
    "    dt = T/n\n",
    "    sqrt_dt = np.sqrt(dt)\n",
    "    for l in range(dim):\n",
    "        Y[l,0] = x0\n",
    "        for i in range(n):\n",
    "            Y[l,i+1] = Y[l,i] + np.multiply(mu(Y[l,i],l,i),dt) + sigma(Y[l,i],l,i)*sqrt_dt*(W[l,i+1]-W[l,i])\n",
    "    \n",
    "    return Y\n",
    "\n",
    "def sabr(alpha,beta,T,W,Z,V0,S0):\n",
    "    assert(beta>0)\n",
    "\n",
    "    def mu2(V,i,k):\n",
    "        return 0.0\n",
    "    \n",
    "    def sigma2(V,i,k):\n",
    "        return np.multiply(alpha,V)\n",
    "    \n",
    "    V = euler_maruyama(mu2,sigma2,T,V0,Z)\n",
    "    \n",
    "    def mu1(S,i,k):\n",
    "        return 0.0\n",
    "    \n",
    "    def sigma1(S,i,k):\n",
    "        return np.multiply(V[i,k],np.power(np.maximum(0.0,S),beta))\n",
    "    \n",
    "    S = euler_maruyama(mu1,sigma1,T,S0,W)\n",
    "    \n",
    "    return S,V\n",
    "\n",
    "def price_pred(alpha,beta,rho,n,dim,T,K,V0,S0):\n",
    "    W,Z = corr_brownian_motion(n,T,dim,rho)\n",
    "    S,V = sabr(alpha,beta,T,W,Z,V0,S0)\n",
    "    S_T = S[:,n]\n",
    "    P = np.exp(-r*T) * np.mean(np.maximum(S_T-K,np.zeros(dim)))\n",
    "    \n",
    "    return P\n"
   ]
  },
  {
   "cell_type": "code",
   "execution_count": 42,
   "metadata": {},
   "outputs": [],
   "source": [
    "data = np.zeros((num_contract_params+1,num_data_points))\n",
    "for i in range(num_sample_patches):\n",
    "    for j in range(num_maturities):\n",
    "        strike_low = contract_bounds[0,0]\n",
    "        T = maturity_low + j * maturities_distance\n",
    "        for k in range(num_strikes):\n",
    "            K = strike_low + k * strikes_distance\n",
    "            n = 100\n",
    "            dim =50\n",
    "            data[0,i*num_maturities*num_strikes+j*num_strikes+k] = T\n",
    "            data[1,i*num_maturities*num_strikes+j*num_strikes+k] = K\n",
    "            data[2,i*num_maturities*num_strikes+j*num_strikes+k] = price_pred(alpha_true,beta_true,rho_true,n,dim,T,K,V0,S0)\n",
    "            \n",
    "            "
   ]
  },
  {
   "cell_type": "code",
   "execution_count": 43,
   "metadata": {},
   "outputs": [
    {
     "output_type": "stream",
     "name": "stdout",
     "text": "\n"
    }
   ],
   "source": []
  },
  {
   "cell_type": "markdown",
   "metadata": {},
   "source": [
    "## Load Models"
   ]
  },
  {
   "cell_type": "code",
   "execution_count": 70,
   "metadata": {},
   "outputs": [
    {
     "output_type": "stream",
     "name": "stdout",
     "text": "INFO:tensorflow:Restoring parameters from ../SABR_Experiments/models/checkpoint\n"
    },
    {
     "output_type": "error",
     "ename": "DataLossError",
     "evalue": "Unable to open table file ../SABR_Experiments/models/checkpoint: Data loss: not an sstable (bad magic number): perhaps your file is in a different file format and you need to use a different restore operator?\n\t [[Node: save/RestoreV2 = RestoreV2[dtypes=[DT_FLOAT, DT_FLOAT, DT_FLOAT, DT_FLOAT, DT_FLOAT, ..., DT_FLOAT, DT_FLOAT, DT_FLOAT, DT_FLOAT, DT_FLOAT], _device=\"/job:localhost/replica:0/task:0/device:CPU:0\"](_arg_save/Const_0_0, save/RestoreV2/tensor_names, save/RestoreV2/shape_and_slices)]]\n\nCaused by op 'save/RestoreV2', defined at:\n  File \"/Users/robinvogtland/opt/anaconda3/envs/slt-ce/lib/python3.5/runpy.py\", line 193, in _run_module_as_main\n    \"__main__\", mod_spec)\n  File \"/Users/robinvogtland/opt/anaconda3/envs/slt-ce/lib/python3.5/runpy.py\", line 85, in _run_code\n    exec(code, run_globals)\n  File \"/Users/robinvogtland/opt/anaconda3/envs/slt-ce/lib/python3.5/site-packages/ipykernel_launcher.py\", line 16, in <module>\n    app.launch_new_instance()\n  File \"/Users/robinvogtland/opt/anaconda3/envs/slt-ce/lib/python3.5/site-packages/traitlets/config/application.py\", line 658, in launch_instance\n    app.start()\n  File \"/Users/robinvogtland/opt/anaconda3/envs/slt-ce/lib/python3.5/site-packages/ipykernel/kernelapp.py\", line 499, in start\n    self.io_loop.start()\n  File \"/Users/robinvogtland/opt/anaconda3/envs/slt-ce/lib/python3.5/site-packages/tornado/platform/asyncio.py\", line 132, in start\n    self.asyncio_loop.run_forever()\n  File \"/Users/robinvogtland/opt/anaconda3/envs/slt-ce/lib/python3.5/asyncio/base_events.py\", line 421, in run_forever\n    self._run_once()\n  File \"/Users/robinvogtland/opt/anaconda3/envs/slt-ce/lib/python3.5/asyncio/base_events.py\", line 1425, in _run_once\n    handle._run()\n  File \"/Users/robinvogtland/opt/anaconda3/envs/slt-ce/lib/python3.5/asyncio/events.py\", line 127, in _run\n    self._callback(*self._args)\n  File \"/Users/robinvogtland/opt/anaconda3/envs/slt-ce/lib/python3.5/site-packages/tornado/platform/asyncio.py\", line 122, in _handle_events\n    handler_func(fileobj, events)\n  File \"/Users/robinvogtland/opt/anaconda3/envs/slt-ce/lib/python3.5/site-packages/tornado/stack_context.py\", line 300, in null_wrapper\n    return fn(*args, **kwargs)\n  File \"/Users/robinvogtland/opt/anaconda3/envs/slt-ce/lib/python3.5/site-packages/zmq/eventloop/zmqstream.py\", line 450, in _handle_events\n    self._handle_recv()\n  File \"/Users/robinvogtland/opt/anaconda3/envs/slt-ce/lib/python3.5/site-packages/zmq/eventloop/zmqstream.py\", line 480, in _handle_recv\n    self._run_callback(callback, msg)\n  File \"/Users/robinvogtland/opt/anaconda3/envs/slt-ce/lib/python3.5/site-packages/zmq/eventloop/zmqstream.py\", line 432, in _run_callback\n    callback(*args, **kwargs)\n  File \"/Users/robinvogtland/opt/anaconda3/envs/slt-ce/lib/python3.5/site-packages/tornado/stack_context.py\", line 300, in null_wrapper\n    return fn(*args, **kwargs)\n  File \"/Users/robinvogtland/opt/anaconda3/envs/slt-ce/lib/python3.5/site-packages/ipykernel/kernelbase.py\", line 283, in dispatcher\n    return self.dispatch_shell(stream, msg)\n  File \"/Users/robinvogtland/opt/anaconda3/envs/slt-ce/lib/python3.5/site-packages/ipykernel/kernelbase.py\", line 233, in dispatch_shell\n    handler(stream, idents, msg)\n  File \"/Users/robinvogtland/opt/anaconda3/envs/slt-ce/lib/python3.5/site-packages/ipykernel/kernelbase.py\", line 399, in execute_request\n    user_expressions, allow_stdin)\n  File \"/Users/robinvogtland/opt/anaconda3/envs/slt-ce/lib/python3.5/site-packages/ipykernel/ipkernel.py\", line 208, in do_execute\n    res = shell.run_cell(code, store_history=store_history, silent=silent)\n  File \"/Users/robinvogtland/opt/anaconda3/envs/slt-ce/lib/python3.5/site-packages/ipykernel/zmqshell.py\", line 537, in run_cell\n    return super(ZMQInteractiveShell, self).run_cell(*args, **kwargs)\n  File \"/Users/robinvogtland/opt/anaconda3/envs/slt-ce/lib/python3.5/site-packages/IPython/core/interactiveshell.py\", line 2662, in run_cell\n    raw_cell, store_history, silent, shell_futures)\n  File \"/Users/robinvogtland/opt/anaconda3/envs/slt-ce/lib/python3.5/site-packages/IPython/core/interactiveshell.py\", line 2785, in _run_cell\n    interactivity=interactivity, compiler=compiler, result=result)\n  File \"/Users/robinvogtland/opt/anaconda3/envs/slt-ce/lib/python3.5/site-packages/IPython/core/interactiveshell.py\", line 2901, in run_ast_nodes\n    if self.run_code(code, result):\n  File \"/Users/robinvogtland/opt/anaconda3/envs/slt-ce/lib/python3.5/site-packages/IPython/core/interactiveshell.py\", line 2961, in run_code\n    exec(code_obj, self.user_global_ns, self.user_ns)\n  File \"<ipython-input-70-ada5042914c5>\", line 2, in <module>\n    imported_meta = tf.train.import_meta_graph(\"../SABR_Experiments/models/sabr_cnn.meta\")\n  File \"/Users/robinvogtland/opt/anaconda3/envs/slt-ce/lib/python3.5/site-packages/tensorflow/python/training/saver.py\", line 1939, in import_meta_graph\n    **kwargs)\n  File \"/Users/robinvogtland/opt/anaconda3/envs/slt-ce/lib/python3.5/site-packages/tensorflow/python/framework/meta_graph.py\", line 744, in import_scoped_meta_graph\n    producer_op_list=producer_op_list)\n  File \"/Users/robinvogtland/opt/anaconda3/envs/slt-ce/lib/python3.5/site-packages/tensorflow/python/util/deprecation.py\", line 454, in new_func\n    return func(*args, **kwargs)\n  File \"/Users/robinvogtland/opt/anaconda3/envs/slt-ce/lib/python3.5/site-packages/tensorflow/python/framework/importer.py\", line 442, in import_graph_def\n    _ProcessNewOps(graph)\n  File \"/Users/robinvogtland/opt/anaconda3/envs/slt-ce/lib/python3.5/site-packages/tensorflow/python/framework/importer.py\", line 234, in _ProcessNewOps\n    for new_op in graph._add_new_tf_operations(compute_devices=False):  # pylint: disable=protected-access\n  File \"/Users/robinvogtland/opt/anaconda3/envs/slt-ce/lib/python3.5/site-packages/tensorflow/python/framework/ops.py\", line 3289, in _add_new_tf_operations\n    for c_op in c_api_util.new_tf_operations(self)\n  File \"/Users/robinvogtland/opt/anaconda3/envs/slt-ce/lib/python3.5/site-packages/tensorflow/python/framework/ops.py\", line 3289, in <listcomp>\n    for c_op in c_api_util.new_tf_operations(self)\n  File \"/Users/robinvogtland/opt/anaconda3/envs/slt-ce/lib/python3.5/site-packages/tensorflow/python/framework/ops.py\", line 3180, in _create_op_from_tf_operation\n    ret = Operation(c_op, self)\n  File \"/Users/robinvogtland/opt/anaconda3/envs/slt-ce/lib/python3.5/site-packages/tensorflow/python/framework/ops.py\", line 1717, in __init__\n    self._traceback = tf_stack.extract_stack()\n\nDataLossError (see above for traceback): Unable to open table file ../SABR_Experiments/models/checkpoint: Data loss: not an sstable (bad magic number): perhaps your file is in a different file format and you need to use a different restore operator?\n\t [[Node: save/RestoreV2 = RestoreV2[dtypes=[DT_FLOAT, DT_FLOAT, DT_FLOAT, DT_FLOAT, DT_FLOAT, ..., DT_FLOAT, DT_FLOAT, DT_FLOAT, DT_FLOAT, DT_FLOAT], _device=\"/job:localhost/replica:0/task:0/device:CPU:0\"](_arg_save/Const_0_0, save/RestoreV2/tensor_names, save/RestoreV2/shape_and_slices)]]\n",
     "traceback": [
      "\u001b[0;31m---------------------------------------------------------------------------\u001b[0m",
      "\u001b[0;31mDataLossError\u001b[0m                             Traceback (most recent call last)",
      "\u001b[0;32m~/opt/anaconda3/envs/slt-ce/lib/python3.5/site-packages/tensorflow/python/client/session.py\u001b[0m in \u001b[0;36m_do_call\u001b[0;34m(self, fn, *args)\u001b[0m\n\u001b[1;32m   1277\u001b[0m     \u001b[0;32mtry\u001b[0m\u001b[0;34m:\u001b[0m\u001b[0;34m\u001b[0m\u001b[0m\n\u001b[0;32m-> 1278\u001b[0;31m       \u001b[0;32mreturn\u001b[0m \u001b[0mfn\u001b[0m\u001b[0;34m(\u001b[0m\u001b[0;34m*\u001b[0m\u001b[0margs\u001b[0m\u001b[0;34m)\u001b[0m\u001b[0;34m\u001b[0m\u001b[0m\n\u001b[0m\u001b[1;32m   1279\u001b[0m     \u001b[0;32mexcept\u001b[0m \u001b[0merrors\u001b[0m\u001b[0;34m.\u001b[0m\u001b[0mOpError\u001b[0m \u001b[0;32mas\u001b[0m \u001b[0me\u001b[0m\u001b[0;34m:\u001b[0m\u001b[0;34m\u001b[0m\u001b[0m\n",
      "\u001b[0;32m~/opt/anaconda3/envs/slt-ce/lib/python3.5/site-packages/tensorflow/python/client/session.py\u001b[0m in \u001b[0;36m_run_fn\u001b[0;34m(feed_dict, fetch_list, target_list, options, run_metadata)\u001b[0m\n\u001b[1;32m   1262\u001b[0m       return self._call_tf_sessionrun(\n\u001b[0;32m-> 1263\u001b[0;31m           options, feed_dict, fetch_list, target_list, run_metadata)\n\u001b[0m\u001b[1;32m   1264\u001b[0m \u001b[0;34m\u001b[0m\u001b[0m\n",
      "\u001b[0;32m~/opt/anaconda3/envs/slt-ce/lib/python3.5/site-packages/tensorflow/python/client/session.py\u001b[0m in \u001b[0;36m_call_tf_sessionrun\u001b[0;34m(self, options, feed_dict, fetch_list, target_list, run_metadata)\u001b[0m\n\u001b[1;32m   1349\u001b[0m         \u001b[0mself\u001b[0m\u001b[0;34m.\u001b[0m\u001b[0m_session\u001b[0m\u001b[0;34m,\u001b[0m \u001b[0moptions\u001b[0m\u001b[0;34m,\u001b[0m \u001b[0mfeed_dict\u001b[0m\u001b[0;34m,\u001b[0m \u001b[0mfetch_list\u001b[0m\u001b[0;34m,\u001b[0m \u001b[0mtarget_list\u001b[0m\u001b[0;34m,\u001b[0m\u001b[0;34m\u001b[0m\u001b[0m\n\u001b[0;32m-> 1350\u001b[0;31m         run_metadata)\n\u001b[0m\u001b[1;32m   1351\u001b[0m \u001b[0;34m\u001b[0m\u001b[0m\n",
      "\u001b[0;31mDataLossError\u001b[0m: Unable to open table file ../SABR_Experiments/models/checkpoint: Data loss: not an sstable (bad magic number): perhaps your file is in a different file format and you need to use a different restore operator?\n\t [[Node: save/RestoreV2 = RestoreV2[dtypes=[DT_FLOAT, DT_FLOAT, DT_FLOAT, DT_FLOAT, DT_FLOAT, ..., DT_FLOAT, DT_FLOAT, DT_FLOAT, DT_FLOAT, DT_FLOAT], _device=\"/job:localhost/replica:0/task:0/device:CPU:0\"](_arg_save/Const_0_0, save/RestoreV2/tensor_names, save/RestoreV2/shape_and_slices)]]",
      "\nDuring handling of the above exception, another exception occurred:\n",
      "\u001b[0;31mDataLossError\u001b[0m                             Traceback (most recent call last)",
      "\u001b[0;32m<ipython-input-70-ada5042914c5>\u001b[0m in \u001b[0;36m<module>\u001b[0;34m()\u001b[0m\n\u001b[1;32m     13\u001b[0m     \u001b[0;31m#tf.get_operation_by_name('outputs')\u001b[0m\u001b[0;34m\u001b[0m\u001b[0;34m\u001b[0m\u001b[0m\n\u001b[1;32m     14\u001b[0m     \u001b[0;32mwith\u001b[0m \u001b[0mtf\u001b[0m\u001b[0;34m.\u001b[0m\u001b[0mSession\u001b[0m\u001b[0;34m(\u001b[0m\u001b[0;34m)\u001b[0m \u001b[0;32mas\u001b[0m \u001b[0msess\u001b[0m\u001b[0;34m:\u001b[0m\u001b[0;34m\u001b[0m\u001b[0m\n\u001b[0;32m---> 15\u001b[0;31m         \u001b[0mimported_meta\u001b[0m\u001b[0;34m.\u001b[0m\u001b[0mrestore\u001b[0m\u001b[0;34m(\u001b[0m\u001b[0msess\u001b[0m\u001b[0;34m,\u001b[0m \u001b[0;34m'../SABR_Experiments/models/checkpoint'\u001b[0m\u001b[0;34m)\u001b[0m\u001b[0;34m\u001b[0m\u001b[0m\n\u001b[0m\u001b[1;32m     16\u001b[0m         \u001b[0mparams_method_1\u001b[0m \u001b[0;34m=\u001b[0m \u001b[0mdefault_graph\u001b[0m\u001b[0;34m.\u001b[0m\u001b[0mrun\u001b[0m\u001b[0;34m(\u001b[0m\u001b[0moutputs\u001b[0m\u001b[0;34m,\u001b[0m\u001b[0mfeed_dict\u001b[0m\u001b[0;34m=\u001b[0m\u001b[0;34m{\u001b[0m\u001b[0mX\u001b[0m\u001b[0;34m:\u001b[0m \u001b[0mX_test\u001b[0m\u001b[0;34m}\u001b[0m\u001b[0;34m)\u001b[0m\u001b[0;34m\u001b[0m\u001b[0m\n\u001b[1;32m     17\u001b[0m \u001b[0;34m\u001b[0m\u001b[0m\n",
      "\u001b[0;32m~/opt/anaconda3/envs/slt-ce/lib/python3.5/site-packages/tensorflow/python/training/saver.py\u001b[0m in \u001b[0;36mrestore\u001b[0;34m(self, sess, save_path)\u001b[0m\n\u001b[1;32m   1723\u001b[0m       \u001b[0;32melse\u001b[0m\u001b[0;34m:\u001b[0m\u001b[0;34m\u001b[0m\u001b[0m\n\u001b[1;32m   1724\u001b[0m         sess.run(self.saver_def.restore_op_name,\n\u001b[0;32m-> 1725\u001b[0;31m                  {self.saver_def.filename_tensor_name: save_path})\n\u001b[0m\u001b[1;32m   1726\u001b[0m     \u001b[0;32mexcept\u001b[0m \u001b[0merrors\u001b[0m\u001b[0;34m.\u001b[0m\u001b[0mNotFoundError\u001b[0m \u001b[0;32mas\u001b[0m \u001b[0merr\u001b[0m\u001b[0;34m:\u001b[0m\u001b[0;34m\u001b[0m\u001b[0m\n\u001b[1;32m   1727\u001b[0m       \u001b[0;31m# There are three common conditions that might cause this error:\u001b[0m\u001b[0;34m\u001b[0m\u001b[0;34m\u001b[0m\u001b[0m\n",
      "\u001b[0;32m~/opt/anaconda3/envs/slt-ce/lib/python3.5/site-packages/tensorflow/python/client/session.py\u001b[0m in \u001b[0;36mrun\u001b[0;34m(self, fetches, feed_dict, options, run_metadata)\u001b[0m\n\u001b[1;32m    875\u001b[0m     \u001b[0;32mtry\u001b[0m\u001b[0;34m:\u001b[0m\u001b[0;34m\u001b[0m\u001b[0m\n\u001b[1;32m    876\u001b[0m       result = self._run(None, fetches, feed_dict, options_ptr,\n\u001b[0;32m--> 877\u001b[0;31m                          run_metadata_ptr)\n\u001b[0m\u001b[1;32m    878\u001b[0m       \u001b[0;32mif\u001b[0m \u001b[0mrun_metadata\u001b[0m\u001b[0;34m:\u001b[0m\u001b[0;34m\u001b[0m\u001b[0m\n\u001b[1;32m    879\u001b[0m         \u001b[0mproto_data\u001b[0m \u001b[0;34m=\u001b[0m \u001b[0mtf_session\u001b[0m\u001b[0;34m.\u001b[0m\u001b[0mTF_GetBuffer\u001b[0m\u001b[0;34m(\u001b[0m\u001b[0mrun_metadata_ptr\u001b[0m\u001b[0;34m)\u001b[0m\u001b[0;34m\u001b[0m\u001b[0m\n",
      "\u001b[0;32m~/opt/anaconda3/envs/slt-ce/lib/python3.5/site-packages/tensorflow/python/client/session.py\u001b[0m in \u001b[0;36m_run\u001b[0;34m(self, handle, fetches, feed_dict, options, run_metadata)\u001b[0m\n\u001b[1;32m   1098\u001b[0m     \u001b[0;32mif\u001b[0m \u001b[0mfinal_fetches\u001b[0m \u001b[0;32mor\u001b[0m \u001b[0mfinal_targets\u001b[0m \u001b[0;32mor\u001b[0m \u001b[0;34m(\u001b[0m\u001b[0mhandle\u001b[0m \u001b[0;32mand\u001b[0m \u001b[0mfeed_dict_tensor\u001b[0m\u001b[0;34m)\u001b[0m\u001b[0;34m:\u001b[0m\u001b[0;34m\u001b[0m\u001b[0m\n\u001b[1;32m   1099\u001b[0m       results = self._do_run(handle, final_targets, final_fetches,\n\u001b[0;32m-> 1100\u001b[0;31m                              feed_dict_tensor, options, run_metadata)\n\u001b[0m\u001b[1;32m   1101\u001b[0m     \u001b[0;32melse\u001b[0m\u001b[0;34m:\u001b[0m\u001b[0;34m\u001b[0m\u001b[0m\n\u001b[1;32m   1102\u001b[0m       \u001b[0mresults\u001b[0m \u001b[0;34m=\u001b[0m \u001b[0;34m[\u001b[0m\u001b[0;34m]\u001b[0m\u001b[0;34m\u001b[0m\u001b[0m\n",
      "\u001b[0;32m~/opt/anaconda3/envs/slt-ce/lib/python3.5/site-packages/tensorflow/python/client/session.py\u001b[0m in \u001b[0;36m_do_run\u001b[0;34m(self, handle, target_list, fetch_list, feed_dict, options, run_metadata)\u001b[0m\n\u001b[1;32m   1270\u001b[0m     \u001b[0;32mif\u001b[0m \u001b[0mhandle\u001b[0m \u001b[0;32mis\u001b[0m \u001b[0;32mNone\u001b[0m\u001b[0;34m:\u001b[0m\u001b[0;34m\u001b[0m\u001b[0m\n\u001b[1;32m   1271\u001b[0m       return self._do_call(_run_fn, feeds, fetches, targets, options,\n\u001b[0;32m-> 1272\u001b[0;31m                            run_metadata)\n\u001b[0m\u001b[1;32m   1273\u001b[0m     \u001b[0;32melse\u001b[0m\u001b[0;34m:\u001b[0m\u001b[0;34m\u001b[0m\u001b[0m\n\u001b[1;32m   1274\u001b[0m       \u001b[0;32mreturn\u001b[0m \u001b[0mself\u001b[0m\u001b[0;34m.\u001b[0m\u001b[0m_do_call\u001b[0m\u001b[0;34m(\u001b[0m\u001b[0m_prun_fn\u001b[0m\u001b[0;34m,\u001b[0m \u001b[0mhandle\u001b[0m\u001b[0;34m,\u001b[0m \u001b[0mfeeds\u001b[0m\u001b[0;34m,\u001b[0m \u001b[0mfetches\u001b[0m\u001b[0;34m)\u001b[0m\u001b[0;34m\u001b[0m\u001b[0m\n",
      "\u001b[0;32m~/opt/anaconda3/envs/slt-ce/lib/python3.5/site-packages/tensorflow/python/client/session.py\u001b[0m in \u001b[0;36m_do_call\u001b[0;34m(self, fn, *args)\u001b[0m\n\u001b[1;32m   1289\u001b[0m         \u001b[0;32mexcept\u001b[0m \u001b[0mKeyError\u001b[0m\u001b[0;34m:\u001b[0m\u001b[0;34m\u001b[0m\u001b[0m\n\u001b[1;32m   1290\u001b[0m           \u001b[0;32mpass\u001b[0m\u001b[0;34m\u001b[0m\u001b[0m\n\u001b[0;32m-> 1291\u001b[0;31m       \u001b[0;32mraise\u001b[0m \u001b[0mtype\u001b[0m\u001b[0;34m(\u001b[0m\u001b[0me\u001b[0m\u001b[0;34m)\u001b[0m\u001b[0;34m(\u001b[0m\u001b[0mnode_def\u001b[0m\u001b[0;34m,\u001b[0m \u001b[0mop\u001b[0m\u001b[0;34m,\u001b[0m \u001b[0mmessage\u001b[0m\u001b[0;34m)\u001b[0m\u001b[0;34m\u001b[0m\u001b[0m\n\u001b[0m\u001b[1;32m   1292\u001b[0m \u001b[0;34m\u001b[0m\u001b[0m\n\u001b[1;32m   1293\u001b[0m   \u001b[0;32mdef\u001b[0m \u001b[0m_extend_graph\u001b[0m\u001b[0;34m(\u001b[0m\u001b[0mself\u001b[0m\u001b[0;34m)\u001b[0m\u001b[0;34m:\u001b[0m\u001b[0;34m\u001b[0m\u001b[0m\n",
      "\u001b[0;31mDataLossError\u001b[0m: Unable to open table file ../SABR_Experiments/models/checkpoint: Data loss: not an sstable (bad magic number): perhaps your file is in a different file format and you need to use a different restore operator?\n\t [[Node: save/RestoreV2 = RestoreV2[dtypes=[DT_FLOAT, DT_FLOAT, DT_FLOAT, DT_FLOAT, DT_FLOAT, ..., DT_FLOAT, DT_FLOAT, DT_FLOAT, DT_FLOAT, DT_FLOAT], _device=\"/job:localhost/replica:0/task:0/device:CPU:0\"](_arg_save/Const_0_0, save/RestoreV2/tensor_names, save/RestoreV2/shape_and_slices)]]\n\nCaused by op 'save/RestoreV2', defined at:\n  File \"/Users/robinvogtland/opt/anaconda3/envs/slt-ce/lib/python3.5/runpy.py\", line 193, in _run_module_as_main\n    \"__main__\", mod_spec)\n  File \"/Users/robinvogtland/opt/anaconda3/envs/slt-ce/lib/python3.5/runpy.py\", line 85, in _run_code\n    exec(code, run_globals)\n  File \"/Users/robinvogtland/opt/anaconda3/envs/slt-ce/lib/python3.5/site-packages/ipykernel_launcher.py\", line 16, in <module>\n    app.launch_new_instance()\n  File \"/Users/robinvogtland/opt/anaconda3/envs/slt-ce/lib/python3.5/site-packages/traitlets/config/application.py\", line 658, in launch_instance\n    app.start()\n  File \"/Users/robinvogtland/opt/anaconda3/envs/slt-ce/lib/python3.5/site-packages/ipykernel/kernelapp.py\", line 499, in start\n    self.io_loop.start()\n  File \"/Users/robinvogtland/opt/anaconda3/envs/slt-ce/lib/python3.5/site-packages/tornado/platform/asyncio.py\", line 132, in start\n    self.asyncio_loop.run_forever()\n  File \"/Users/robinvogtland/opt/anaconda3/envs/slt-ce/lib/python3.5/asyncio/base_events.py\", line 421, in run_forever\n    self._run_once()\n  File \"/Users/robinvogtland/opt/anaconda3/envs/slt-ce/lib/python3.5/asyncio/base_events.py\", line 1425, in _run_once\n    handle._run()\n  File \"/Users/robinvogtland/opt/anaconda3/envs/slt-ce/lib/python3.5/asyncio/events.py\", line 127, in _run\n    self._callback(*self._args)\n  File \"/Users/robinvogtland/opt/anaconda3/envs/slt-ce/lib/python3.5/site-packages/tornado/platform/asyncio.py\", line 122, in _handle_events\n    handler_func(fileobj, events)\n  File \"/Users/robinvogtland/opt/anaconda3/envs/slt-ce/lib/python3.5/site-packages/tornado/stack_context.py\", line 300, in null_wrapper\n    return fn(*args, **kwargs)\n  File \"/Users/robinvogtland/opt/anaconda3/envs/slt-ce/lib/python3.5/site-packages/zmq/eventloop/zmqstream.py\", line 450, in _handle_events\n    self._handle_recv()\n  File \"/Users/robinvogtland/opt/anaconda3/envs/slt-ce/lib/python3.5/site-packages/zmq/eventloop/zmqstream.py\", line 480, in _handle_recv\n    self._run_callback(callback, msg)\n  File \"/Users/robinvogtland/opt/anaconda3/envs/slt-ce/lib/python3.5/site-packages/zmq/eventloop/zmqstream.py\", line 432, in _run_callback\n    callback(*args, **kwargs)\n  File \"/Users/robinvogtland/opt/anaconda3/envs/slt-ce/lib/python3.5/site-packages/tornado/stack_context.py\", line 300, in null_wrapper\n    return fn(*args, **kwargs)\n  File \"/Users/robinvogtland/opt/anaconda3/envs/slt-ce/lib/python3.5/site-packages/ipykernel/kernelbase.py\", line 283, in dispatcher\n    return self.dispatch_shell(stream, msg)\n  File \"/Users/robinvogtland/opt/anaconda3/envs/slt-ce/lib/python3.5/site-packages/ipykernel/kernelbase.py\", line 233, in dispatch_shell\n    handler(stream, idents, msg)\n  File \"/Users/robinvogtland/opt/anaconda3/envs/slt-ce/lib/python3.5/site-packages/ipykernel/kernelbase.py\", line 399, in execute_request\n    user_expressions, allow_stdin)\n  File \"/Users/robinvogtland/opt/anaconda3/envs/slt-ce/lib/python3.5/site-packages/ipykernel/ipkernel.py\", line 208, in do_execute\n    res = shell.run_cell(code, store_history=store_history, silent=silent)\n  File \"/Users/robinvogtland/opt/anaconda3/envs/slt-ce/lib/python3.5/site-packages/ipykernel/zmqshell.py\", line 537, in run_cell\n    return super(ZMQInteractiveShell, self).run_cell(*args, **kwargs)\n  File \"/Users/robinvogtland/opt/anaconda3/envs/slt-ce/lib/python3.5/site-packages/IPython/core/interactiveshell.py\", line 2662, in run_cell\n    raw_cell, store_history, silent, shell_futures)\n  File \"/Users/robinvogtland/opt/anaconda3/envs/slt-ce/lib/python3.5/site-packages/IPython/core/interactiveshell.py\", line 2785, in _run_cell\n    interactivity=interactivity, compiler=compiler, result=result)\n  File \"/Users/robinvogtland/opt/anaconda3/envs/slt-ce/lib/python3.5/site-packages/IPython/core/interactiveshell.py\", line 2901, in run_ast_nodes\n    if self.run_code(code, result):\n  File \"/Users/robinvogtland/opt/anaconda3/envs/slt-ce/lib/python3.5/site-packages/IPython/core/interactiveshell.py\", line 2961, in run_code\n    exec(code_obj, self.user_global_ns, self.user_ns)\n  File \"<ipython-input-70-ada5042914c5>\", line 2, in <module>\n    imported_meta = tf.train.import_meta_graph(\"../SABR_Experiments/models/sabr_cnn.meta\")\n  File \"/Users/robinvogtland/opt/anaconda3/envs/slt-ce/lib/python3.5/site-packages/tensorflow/python/training/saver.py\", line 1939, in import_meta_graph\n    **kwargs)\n  File \"/Users/robinvogtland/opt/anaconda3/envs/slt-ce/lib/python3.5/site-packages/tensorflow/python/framework/meta_graph.py\", line 744, in import_scoped_meta_graph\n    producer_op_list=producer_op_list)\n  File \"/Users/robinvogtland/opt/anaconda3/envs/slt-ce/lib/python3.5/site-packages/tensorflow/python/util/deprecation.py\", line 454, in new_func\n    return func(*args, **kwargs)\n  File \"/Users/robinvogtland/opt/anaconda3/envs/slt-ce/lib/python3.5/site-packages/tensorflow/python/framework/importer.py\", line 442, in import_graph_def\n    _ProcessNewOps(graph)\n  File \"/Users/robinvogtland/opt/anaconda3/envs/slt-ce/lib/python3.5/site-packages/tensorflow/python/framework/importer.py\", line 234, in _ProcessNewOps\n    for new_op in graph._add_new_tf_operations(compute_devices=False):  # pylint: disable=protected-access\n  File \"/Users/robinvogtland/opt/anaconda3/envs/slt-ce/lib/python3.5/site-packages/tensorflow/python/framework/ops.py\", line 3289, in _add_new_tf_operations\n    for c_op in c_api_util.new_tf_operations(self)\n  File \"/Users/robinvogtland/opt/anaconda3/envs/slt-ce/lib/python3.5/site-packages/tensorflow/python/framework/ops.py\", line 3289, in <listcomp>\n    for c_op in c_api_util.new_tf_operations(self)\n  File \"/Users/robinvogtland/opt/anaconda3/envs/slt-ce/lib/python3.5/site-packages/tensorflow/python/framework/ops.py\", line 3180, in _create_op_from_tf_operation\n    ret = Operation(c_op, self)\n  File \"/Users/robinvogtland/opt/anaconda3/envs/slt-ce/lib/python3.5/site-packages/tensorflow/python/framework/ops.py\", line 1717, in __init__\n    self._traceback = tf_stack.extract_stack()\n\nDataLossError (see above for traceback): Unable to open table file ../SABR_Experiments/models/checkpoint: Data loss: not an sstable (bad magic number): perhaps your file is in a different file format and you need to use a different restore operator?\n\t [[Node: save/RestoreV2 = RestoreV2[dtypes=[DT_FLOAT, DT_FLOAT, DT_FLOAT, DT_FLOAT, DT_FLOAT, ..., DT_FLOAT, DT_FLOAT, DT_FLOAT, DT_FLOAT, DT_FLOAT], _device=\"/job:localhost/replica:0/task:0/device:CPU:0\"](_arg_save/Const_0_0, save/RestoreV2/tensor_names, save/RestoreV2/shape_and_slices)]]\n"
     ]
    }
   ],
   "source": [
    "tf.reset_default_graph()\n",
    "imported_meta = tf.train.import_meta_graph(\"../SABR_Experiments/models/sabr_cnn.meta\")\n",
    "graph = tf.get_default_graph()\n",
    "\n",
    "X_test = np.zeros((1,num_maturities,num_strikes,1))\n",
    "for i in range(num_maturities):\n",
    "    for j in range(num_strikes):\n",
    "        X_test[0,i,j,0] = data[2,i*num_strikes+j]\n",
    "\n",
    "with graph.as_default() as default_graph:                          \n",
    "    #print([op.name for op in graph.get_operations()])\n",
    "    #X = tf.get_variable('Placeholder')\n",
    "    #tf.get_operation_by_name('outputs')\n",
    "    with tf.Session() as sess:\n",
    "        imported_meta.restore(sess, '../SABR_Experiments/models/checkpoint')\n",
    "        params_method_1 = default_graph.run(outputs,feed_dict={X: X_test})\n",
    "\n",
    "print(params_method_1)\n"
   ]
  },
  {
   "cell_type": "code",
   "execution_count": null,
   "metadata": {},
   "outputs": [],
   "source": []
  }
 ],
 "metadata": {
  "language_info": {
   "codemirror_mode": {
    "name": "ipython",
    "version": 3
   },
   "file_extension": ".py",
   "mimetype": "text/x-python",
   "name": "python",
   "nbconvert_exporter": "python",
   "pygments_lexer": "ipython3",
   "version": "3.5.4-final"
  },
  "orig_nbformat": 2,
  "kernelspec": {
   "name": "python35464bitsltceconda48e4663f99f043ab92106a229275bf62",
   "display_name": "Python 3.5.4 64-bit ('slt-ce': conda)"
  }
 },
 "nbformat": 4,
 "nbformat_minor": 2
}